Workbook

Sheet Formula1_2023season_raceResults
A1: Track | B1: Position | C1: No | D1: Driver | E1: Team | F1: Starting Grid | G1: Laps | H1: Time/Retired | I1: Points | J1: Set Fastest Lap | K1: Fastest Lap Time | L1: Track Index
A2: Bahrain | B2: 1 | C2: 1 | D2: Max Verstappen | E2: Red Bull Racing Honda RBPT | F2: 1 | G2: 57 | H2: 0.06524 | I2: 25 | J2: No | K2: 0.0011138426 | L2: 1
A3: Bahrain | B3: 2 | C3: 11 | D3: Sergio Perez | E3: Red Bull Racing Honda RBPT | F3: 2 | G3: 57 | H3: 11.987 | I3: 18 | J3: No | K3: 0.0011150926 | L3: 1
A4: Bahrain | B4: 3 | C4: 14 | D4: Fernando Alonso | E4: Aston Martin Aramco Mercedes | F4: 5 | G4: 57 | H4: 38.637 | I4: 15 | J4: No | K4: 0.0011129167 | L4: 1
A5: Bahrain | B5: 4 | C5: 55 | D5: Carlos Sainz | E5: Ferrari | F5: 4 | G5: 57 | H5: 48.052 | I5: 12 | J5: No | K5: 0.0011241898 | L5: 1
A6: Bahrain | B6: 5 | C6: 44 | D6: Lewis Hamilton | E6: Mercedes | F6: 7 | G6: 57 | H6: 50.977 | I6: 10 | J6: No | K6: 0.0011174306 | L6: 1
A7: Bahrain | B7: 6 | C7: 18 | D7: Lance Stroll | E7: Aston Martin Aramco Mercedes | F7: 8 | G7: 57 | H7: 54.502 | I7: 8 | J7: No | K7: 0.0011174306 | L7: 1
A8: Bahrain | B8: 7 | C8: 63 | D8: George Russell | E8: Mercedes | F8: 6 | G8: 57 | H8: 55.873 | I8: 6 | J8: No | K8: 0.0011252431 | L8: 1
A9: Bahrain | B9: 8 | C9: 77 | D9: Valtteri Bottas | E9: Alfa Romeo Ferrari | F9: 12 | G9: 57 | H9: 72.647 | I9: 4 | J9: No | K9: 0.0011270718 | L9: 1
A10: Bahrain | B10: 9 | C10: 10 | D10: Pierre Gasly | E10: Alpine Renault | F10: 20 | G10: 57 | H10: 73.753 | I10: 2 | J10: No | K10: 0.0011003241 | L10: 1
A11: Bahrain | B11: 10 | C11: 23 | D11: Alexander Albon | E11: Williams Mercedes | F11: 15 | G11: 57 | H11: 89.774 | I11: 1 | J11: No | K11: 0.0011243519 | L11: 1
A12: Bahrain | B12: 11 | C12: 22 | D12: Yuki Tsunoda | E12: AlphaTauri Honda RBPT | F12: 14 | G12: 57 | H12: 90.87 | I12: 0 | J12: No | K12: 0.0011184838 | L12: 1
A13: Bahrain | B13: 12 | C13: 2 | D13: Logan Sargeant | E13: Williams Mercedes | F13: 16 | G13: 56 | H13: +1 lap | I13: 0 | J13: No | K13: 0.0011115394 | L13: 1
A14: Bahrain | B14: 13 | C14: 20 | D14: Kevin Magnussen | E14: Haas Ferrari | F14: 17 | G14: 56 | H14: +1 lap | I14: 0 | J14: No | K14: 0.0011165625 | L14: 1
A15: Bahrain | B15: 14 | C15: 21 | D15: Nyck De Vries | E15: AlphaTauri Honda RBPT | F15: 19 | G15: 56 | H15: +1 lap | I15: 0 | J15: No | K15: 0.0011308912 | L15: 1
A16: Bahrain | B16: 15 | C16: 27 | D16: Nico Hulkenberg | E16: Haas Ferrari | F16: 10 | G16: 56 | H16: +1 lap | I16: 0 | J16: No | K16: 0.0011182407 | L16: 1
A17: Bahrain | B17: 16 | C17: 24 | D17: Guanyu Zhou | E17: Alfa Romeo Ferrari | F17: 13 | G17: 56 | H17: +1 lap | I17: 0 | J17: Yes | K17: 0.0010879167 | L17: 1
A18: Bahrain | B18: 17 | C18: 4 | D18: Lando Norris | E18: McLaren Mercedes | F18: 11 | G18: 55 | H18: +2 laps | I18: 0 | J18: No | K18: 0.0011090509 | L18: 1
A19: Bahrain | B19: NC | C19: 31 | D19: Esteban Ocon | E19: Alpine Renault | F19: 9 | G19: 41 | H19: DNF | I19: 0 | J19: No | K19: 0.0011203356 | L19: 1
A20: Bahrain | B20: NC | C20: 16 | D20: Charles Leclerc | E20: Ferrari | F20: 3 | G20: 39 | H20: DNF | I20: 0 | J20: No | K20: 0.0011246528 | L20: 1
A21: Bahrain | B21: NC | C21: 81 | D21: Oscar Piastri | E21: McLaren Mercedes | F21: 18 | G21: 13 | H21: DNF | I21: 0 | J21: No | K21: 0.0011654051 | L21: 1
A22: Saudi Arabia | B22: 1 | C22: 11 | D22: Sergio Perez | E22: Red Bull Racing Honda RBPT | F22: 1 | G22: 50 | H22: 0.056422384 | I22: 25 | J22: No | K22: 0.0010669907 | L22: =L2+1 -> 2
A23: Saudi Arabia | B23: 2 | C23: 1 | D23: Max Verstappen | E23: Red Bull Racing Honda RBPT | F23: 15 | G23: 50 | H23: 5.335 | I23: 19 | J23: Yes | K23: 0.0010637269 | L23: =L3+1 -> 2
A24: Saudi Arabia | B24: 3 | C24: 14 | D24: Fernando Alonso | E24: Aston Martin Aramco Mercedes | F24: 2 | G24: 50 | H24: 20.728 | I24: 15 | J24: No | K24: 0.0010675926 | L24: =L4+1 -> 2
A25: Saudi Arabia | B25: 4 | C25: 63 | D25: George Russell | E25: Mercedes | F25: 3 | G25: 50 | H25: 25.866 | I25: 12 | J25: No | K25: 0.0010698264 | L25: =L5+1 -> 2
A26: Saudi Arabia | B26: 5 | C26: 44 | D26: Lewis Hamilton | E26: Mercedes | F26: 7 | G26: 50 | H26: 31.065 | I26: 10 | J26: No | K26: 0.001075706 | L26: =L6+1 -> 2
A27: Saudi Arabia | B27: 6 | C27: 55 | D27: Carlos Sainz | E27: Ferrari | F27: 4 | G27: 50 | H27: 35.876 | I27: 8 | J27: No | K27: 0.0010743287 | L27: =L7+1 -> 2
A28: Saudi Arabia | B28: 7 | C28: 16 | D28: Charles Leclerc | E28: Ferrari | F28: 12 | G28: 50 | H28: 43.162 | I28: 6 | J28: No | K28: 0.001077037 | L28: =L8+1 -> 2
A29: Saudi Arabia | B29: 8 | C29: 31 | D29: Esteban Ocon | E29: Alpine Renault | F29: 6 | G29: 50 | H29: 52.832 | I29: 4 | J29: No | K29: 0.0010789583 | L29: =L9+1 -> 2
A30: Saudi Arabia | B30: 9 | C30: 10 | D30: Pierre Gasly | E30: Alpine Renault | F30: 9 | G30: 50 | H30: 54.747 | I30: 2 | J30: No | K30: 0.0010809259 | L30: =L10+1 -> 2
A31: Saudi Arabia | B31: 10 | C31: 20 | D31: Kevin Magnussen | E31: Haas Ferrari | F31: 13 | G31: 50 | H31: 64.826 | I31: 1 | J31: No | K31: 0.0010807176 | L31: =L11+1 -> 2
A32: Saudi Arabia | B32: 11 | C32: 22 | D32: Yuki Tsunoda | E32: AlphaTauri Honda RBPT | F32: 16 | G32: 50 | H32: 67.494 | I32: 0 | J32: No | K32: 0.0010871644 | L32: =L12+1 -> 2
A33: Saudi Arabia | B33: 12 | C33: 27 | D33: Nico Hulkenberg | E33: Haas Ferrari | F33: 10 | G33: 50 | H33: 70.588 | I33: 0 | J33: No | K33: 0.0010854167 | L33: =L13+1 -> 2
... A38: Saudi Arabia | B38: 17 | C38: 4 | D38: Lando Norris | E38: McLaren Mercedes | F38: 19 | G38: 50 | H38: 86.445 | I38: 0 | J38: No | K38: 0.001089375 | L38: =L18+1 -> 2
A39: Saudi Arabia | B39: 18 | C39: 77 | D39: Valtteri Bottas | E39: Alfa Romeo Ferrari | F39: 14 | G39: 49 | H39: +1 lap | I39: 0 | J39: No | K39: 0.0010924074 | L39: =L19+1 -> 2
A40: Saudi Arabia | B40: NC | C40: 23 | D40: Alexander Albon | E40: Williams Mercedes | F40: 17 | G40: 27 | H40: DNF | I40: 0 | J40: No | K40: 0.0011060995 | L40: =L20+1 -> 2
A41: Saudi Arabia | B41: NC | C41: 18 | D41: Lance Stroll | E41: Aston Martin Aramco Mercedes | F41: 5 | G41: 16 | H41: DNF | I41: 0 | J41: No | K41: 0.0011011574 | L41: =L21+1 -> 2
A42: Australia | B42: 1 | C42: 1 | D42: Max Verstappen | E42: Red Bull Racing Honda RBPT | F42: 1 | G42: 58 | H42: 0.10588392 | I42: 25 | J42: No | K42: 0.00092988426 | L42: =L22+1 -> 3
A43: Australia | B43: 2 | C43: 44 | D43: Lewis Hamilton | E43: Mercedes | F43: 3 | G43: 58 | H43: 0.179 | I43: 18 | J43: No | K43: 0.00093302083 | L43: =L23+1 -> 3
A44: Australia | B44: 3 | C44: 14 | D44: Fernando Alonso | E44: Aston Martin Aramco Mercedes | F44: 4 | G44: 58 | H44: 0.769 | I44: 15 | J44: No | K44: 0.00093143519 | L44: =L24+1 -> 3
...

Sheet Formula1_2024season_raceResults
A1: Track | B1: Position | C1: No | D1: Driver | E1: Team | F1: Starting Grid | G1: Laps | H1: Time/Retired | I1: Points | J1: Set Fastest Lap | K1: Fastest Lap Time | L1: Track Index
A2: Bahrain | B2: 1 | C2: 1 | D2: Max Verstappen | E2: Red Bull Racing Honda RBPT | F2: 1 | G2: 57 | H2: 0.063712292 | I2: 26 | J2: Yes | K2: 0.0010718519 | L2: 1
A3: Bahrain | B3: 2 | C3: 11 | D3: Sergio Perez | E3: Red Bull Racing Honda RBPT | F3: 5 | G3: 57 | H3: 22.457 | I3: 18 | J3: No | K3: 0.0010921759 | L3: 1
A4: Bahrain | B4: 3 | C4: 55 | D4: Carlos Sainz | E4: Ferrari | F4: 4 | G4: 57 | H4: 25.11 | I4: 15 | J4: No | K4: 0.001093831 | L4: 1
A5: Bahrain | B5: 4 | C5: 16 | D5: Charles Leclerc | E5: Ferrari | F5: 2 | G5: 57 | H5: 39.669 | I5: 12 | J5: No | K5: 0.0010890046 | L5: 1
A6: Bahrain | B6: 5 | C6: 63 | D6: George Russell | E6: Mercedes | F6: 3 | G6: 57 | H6: 46.788 | I6: 10 | J6: No | K6: 0.0011002894 | L6: 1
A7: Bahrain | B7: 6 | C7: 4 | D7: Lando Norris | E7: McLaren Mercedes | F7: 7 | G7: 57 | H7: 48.458 | I7: 8 | J7: No | K7: 0.0010934722 | L7: 1
A8: Bahrain | B8: 7 | C8: 44 | D8: Lewis Hamilton | E8: Mercedes | F8: 9 | G8: 57 | H8: 50.324 | I8: 6 | J8: No | K8: 0.0010963194 | L8: 1
A9: Bahrain | B9: 8 | C9: 81 | D9: Oscar Piastri | E9: McLaren Mercedes | F9: 8 | G9: 57 | H9: 56.082 | I9: 4 | J9: No | K9: 0.0010993403 | L9: 1
A10: Bahrain | B10: 9 | C10: 14 | D10: Fernando Alonso | E10: Aston Martin Aramco Mercedes | F10: 6 | G10: 57 | H10: 74.887 | I10: 2 | J10: No | K10: 0.0010902662 | L10: 1
A11: Bahrain | B11: 10 | C11: 18 | D11: Lance Stroll | E11: Aston Martin Aramco Mercedes | F11: 12 | G11: 57 | H11: 93.216 | I11: 1 | J11: No | K11: 0.0011068519 | L11: 1
A12: Bahrain | B12: 11 | C12: 24 | D12: Guanyu Zhou | E12: Kick Sauber Ferrari | F12: 17 | G12: 56 | H12: +1 lap | I12: 0 | J12: No | K12: 0.001104838 | L12: 1
A13: Bahrain | B13: 12 | C13: 20 | D13: Kevin Magnussen | E13: Haas Ferrari | F13: 15 | G13: 56 | H13: +1 lap | I13: 0 | J13: No | K13: 0.0011061343 | L13: 1
A14: Bahrain | B14: 13 | C14: 3 | D14: Daniel Ricciardo | E14: RB Honda RBPT | F14: 14 | G14: 56 | H14: +1 lap | I14: 0 | J14: No | K14: 0.0011014236 | L14: 1
A15: Bahrain | B15: 14 | C15: 22 | D15: Yuki Tsunoda | E15: RB Honda RBPT | F15: 11 | G15: 56 | H15: +1 lap | I15: 0 | J15: No | K15: 0.0011091782 | L15: 1
A16: Bahrain | B16: 15 | C16: 23 | D16: Alexander Albon | E16: Williams Mercedes | F16: 13 | G16: 56 | H16: +1 lap | I16: 0 | J16: No | K16: 0.0011079051 | L16: 1
A17: Bahrain | B17: 16 | C17: 27 | D17: Nico Hulkenberg | E17: Haas Ferrari | F17: 10 | G17: 56 | H17: +1 lap | I17: 0 | J17: No | K17: 0.0010976157 | L17: 1
A18: Bahrain | B18: 17 | C18: 31 | D18: Esteban Ocon | E18: Alpine Renault | F18: 19 | G18: 56 | H18: +1 lap | I18: 0 | J18: No | K18: 0.0011137269 | L18: 1
A19: Bahrain | B19: 18 | C19: 10 | D19: Pierre Gasly | E19: Alpine Renault | F19: 20 | G19: 56 | H19: +1 lap | I19: 0 | J19: No | K19: 0.0010972801 | L19: 1
A20: Bahrain | B20: 19 | C20: 77 | D20: Valtteri Bottas | E20: Kick Sauber Ferrari | F20: 16 | G20: 56 | H20: +1 lap | I20: 0 | J20: No | K20: 0.0011134491 | L20: 1
A21: Bahrain | B21: 20 | C21: 2 | D21: Logan Sargeant | E21: Williams Mercedes | F21: 18 | G21: 55 | H21: +2 laps | I21: 0 | J21: No | K21: 0.0010964699 | L21: 1
A22: Saudi Arabia | B22: 1 | C22: 1 | D22: Max Verstappen | E22: Red Bull Racing Honda RBPT | F22: 1 | G22: 50 | H22: 0.0560564 | I22: 25 | J22: No | K22: 0.0010621875 | L22: =L2+1 -> 2
A23: Saudi Arabia | B23: 2 | C23: 11 | D23: Sergio Perez | E23: Red Bull Racing Honda RBPT | F23: 3 | G23: 50 | H23: 13.643 | I23: 18 | J23: No | K23: 0.0010679745 | L23: =L3+1 -> 2
A24: Saudi Arabia | B24: 3 | C24: 16 | D24: Charles Leclerc | E24: Ferrari | F24: 2 | G24: 50 | H24: 18.639 | I24: 16 | J24: Yes | K24: 0.0010605556 | L24: =L4+1 -> 2
A25: Saudi Arabia | B25: 4 | C25: 81 | D25: Oscar Piastri | E25: McLaren Mercedes | F25: 5 | G25: 50 | H25: 32.007 | I25: 12 | J25: No | K25: 0.0010684028 | L25: =L5+1 -> 2
A26: Saudi Arabia | B26: 5 | C26: 14 | D26: Fernando Alonso | E26: Aston Martin Aramco Mercedes | F26: 4 | G26: 50 | H26: 35.759 | I26: 10 | J26: No | K26: 0.001069294 | L26: =L6+1 -> 2
A27: Saudi Arabia | B27: 6 | C27: 63 | D27: George Russell | E27: Mercedes | F27: 7 | G27: 50 | H27: 39.936 | I27: 8 | J27: No | K27: 0.0010677546 | L27: =L7+1 -> 2
A28: Saudi Arabia | B28: 7 | C28: 38 | D28: Oliver Bearman | E28: Ferrari | F28: 11 | G28: 50 | H28: 42.679 | I28: 6 | J28: No | K28: 0.0010669676 | L28: =L8+1 -> 2
A29: Saudi Arabia | B29: 8 | C29: 4 | D29: Lando Norris | E29: McLaren Mercedes | F29: 6 | G29: 50 | H29: 45.708 | I29: 4 | J29: No | K29: 0.0010641667 | L29: =L9+1 -> 2
A30: Saudi Arabia | B30: 9 | C30: 44 | D30: Lewis Hamilton | E30: Mercedes | F30: 8 | G30: 50 | H30: 47.391 | I30: 2 | J30: No | K30: 0.001061875 | L30: =L10+1 -> 2
A31: Saudi Arabia | B31: 10 | C31: 27 | D31: Nico Hulkenberg | E31: Haas Ferrari | F31: 15 | G31: 50 | H31: 76.996 | I31: 1 | J31: No | K31: 0.0010690509 | L31: =L11+1 -> 2
A32: Saudi Arabia | B32: 11 | C32: 23 | D32: Alexander Albon | E32: Williams Mercedes | F32: 12 | G32: 50 | H32: 88.354 | I32: 0 | J32: No | K32: 0.0010683681 | L32: =L12+1 -> 2
A33: Saudi Arabia | B33: 12 | C33: 20 | D33: Kevin Magnussen | E33: Haas Ferrari | F33: 13 | G33: 50 | H33: 105.737 | I33: 0 | J33: No | K33: 0.0010687269 | L33: =L13+1 -> 2
A34: Saudi Arabia | B34: 13 | C34: 31 | D34: Esteban Ocon | E34: Alpine Renault | F34: 17 | G34: 49 | H34: +1 lap | I34: 0 | J34: No | K34: 0.001081956 | L34: =L14+1 -> 2
A35: Saudi Arabia | B35: 14 | C35: 2 | D35: Logan Sargeant | E35: Williams Mercedes | F35: 19 | G35: 49 | H35: +1 lap | I35: 0 | J35: No | K35: 0.0010766898 | L35: =L15+1 -> 2
A36: Saudi Arabia | B36: 15 | C36: 22 | D36: Yuki Tsunoda | E36: RB Honda RBPT | F36: 9 | G36: 49 | H36: +1 lap | I36: 0 | J36: No | K36: 0.0010824421 | L36: =L16+1 -> 2
A37: Saudi Arabia | B37: 16 | C37: 3 | D37: Daniel Ricciardo | E37: RB Honda RBPT | F37: 14 | G37: 49 | H37: +1 lap | I37: 0 | J37: No | K37: 0.0010801273 | L37: =L17+1 -> 2
A38: Saudi Arabia | B38: 17 | C38: 77 | D38: Valtteri Bottas | E38: Kick Sauber Ferrari | F38: 16 | G38: 49 | H38: +1 lap | I38: 0 | J38: No | K38: 0.0010729861 | L38: =L18+1 -> 2
A39: Saudi Arabia | B39: 18 | C39: 24 | D39: Guanyu Zhou | E39: Kick Sauber Ferrari | F39: 20 | G39: 49 | H39: +1 lap | I39: 0 | J39: No | K39: 0.0010672222 | L39: =L19+1 -> 2
A40: Saudi Arabia | B40: NC | C40: 18 | D40: Lance Stroll | E40: Aston Martin Aramco Mercedes | F40: 10 | G40: 5 | H40: DNF | I40: 0 | J40: No | K40: 0.0011060185 | L40: =L20+1 -> 2
...

Sheet Sprint Results
A1: Track | B1: Position | C1: No | D1: Driver | E1: Team | F1: Starting Grid | G1: Laps | H1: Time/Retired | I1: Points
A2: China | B2: 1 | C2: 1 | D2: Max Verstappen | E2: Red Bull Racing Honda RBPT | F2: 4 | G2: 19 | H2: 0.022276157 | I2: 8
A3: China | B3: 2 | C3: 44 | D3: Lewis Hamilton | E3: Mercedes | F3: 2 | G3: 19 | H3: 13.043 | I3: 7
A4: China | B4: 3 | C4: 11 | D4: Sergio Perez | E4: Red Bull Racing Honda RBPT | F4: 6 | G4: 19 | H4: 15.258 | I4: 6
A5: China | B5: 4 | C5: 16 | D5: Charles Leclerc | E5: Ferrari | F5: 7 | G5: 19 | H5: 17.486 | I5: 5
A6: China | B6: 5 | C6: 55 | D6: Carlos Sainz | E6: Ferrari | F6: 5 | G6: 19 | H6: 20.696 | I6: 4
A7: China | B7: 6 | C7: 4 | D7: Lando Norris | E7: McLaren Mercedes | F7: 1 | G7: 19 | H7: 22.088 | I7: 3
A8: China | B8: 7 | C8: 81 | D8: Oscar Piastri | E8: McLaren Mercedes | F8: 8 | G8: 19 | H8: 24.713 | I8: 2
A9: China | B9: 8 | C9: 63 | D9: George Russell | E9: Mercedes | F9: 11 | G9: 19 | H9: 25.696 | I9: 1
A10: China | B10: 9 | C10: 24 | D10: Guanyu Zhou | E10: Kick Sauber Ferrari | F10: 10 | G10: 19 | H10: 31.951 | I10: 0
A11: China | B11: 10 | C11: 20 | D11: Kevin Magnussen | E11: Haas Ferrari | F11: 12 | G11: 19 | H11: 37.398 | I11: 0
A12: China | B12: 11 | C12: 3 | D12: Daniel Ricciardo | E12: RB Honda RBPT | F12: 14 | G12: 19 | H12: 37.84 | I12: 0
A13: China | B13: 12 | C13: 77 | D13: Valtteri Bottas | E13: Kick Sauber Ferrari | F13: 9 | G13: 19 | H13: 38.295 | I13: 0
... A20: China | B20: 19 | C20: 27 | D20: Nico Hulkenberg | E20: Haas Ferrari | F20: 13 | G20: 19 | H20: 49.63 | I20: 0
A21: China | B21: 20 | C21: 14 | D21: Fernando Alonso | E21: Aston Martin Aramco Mercedes | F21: 3 | G21: 17 | H21: DNF | I21: 0
A22: Miami | B22: 1 | C22: 1 | D22: Max Verstappen | E22: Red Bull Racing Honda RBPT | F22: 1 | G22: 19 | H22: 0.021891007 | I22: 8
A23: Miami | B23: 2 | C23: 16 | D23: Charles Leclerc | E23: Ferrari | F23: 2 | G23: 19 | H23: 3.371 | I23: 7
A24: Miami | B24: 3 | C24: 11 | D24: Sergio Perez | E24: Red Bull Racing Honda RBPT | F24: 3 | G24: 19 | H24: 5.095 | I24: 6
A25: Miami | B25: 4 | C25: 3 | D25: Daniel Ricciardo | E25: RB Honda RBPT | F25: 4 | G25: 19 | H25: 14.971 | I25: 5
A26: Miami | B26: 5 | C26: 55 | D26: Carlos Sainz | E26: Ferrari | F26: 5 | G26: 19 | H26: 15.222 | I26: 4
A27: Miami | B27: 6 | C27: 81 | D27: Oscar Piastri | E27: McLaren Mercedes | F27: 6 | G27: 19 | H27: 15.75 | I27: 3
A28: Miami | B28: 7 | C28: 27 | D28: Nico Hulkenberg | E28: Haas Ferrari | F28: 10 | G28: 19 | H28: 22.054 | I28: 2
A29: Miami | B29: 8 | C29: 22 | D29: Yuki Tsunoda | E29: RB Honda RBPT | F29: 15 | G29: 19 | H29: 29.816 | I29: 1
A30: Miami | B30: 9 | C30: 10 | D30: Pierre Gasly | E30: Alpine Renault | F30: 16 | G30: 19 | H30: 31.88 | I30: 0
A31: Miami | B31: 10 | C31: 2 | D31: Logan Sargeant | E31: Williams Mercedes | F31: 18 | G31: 19 | H31: 34.355 | I31: 0
A32: Miami | B32: 11 | C32: 24 | D32: Guanyu Zhou | E32: Kick Sauber Ferrari | F32: 17 | G32: 19 | H32: 35.078 | I32: 0
A33: Miami | B33: 12 | C33: 63 | D33: George Russell | E33: Mercedes | F33: 11 | G33: 19 | H33: 35.755 | I33: 0
... A39: Miami | B39: 18 | C39: 20 | D39: Kevin Magnussen | E39: Haas Ferrari | F39: 14 | G39: 19 | H39: 66.303 | I39: 0
A40: Miami | B40: NC | C40: 18 | D40: Lance Stroll | E40: Aston Martin Aramco Mercedes | F40: 7 | G40: 1 | H40: DNF | I40: 0
A41: Miami | B41: NC | C41: 4 | D41: Lando Norris | E41: McLaren Mercedes | F41: 9 | G41: 0 | H41: DNF | I41: 0
A42: Austria | B42: 1 | C42: 1 | D42: Max Verstappen | E42: Red Bull Racing Honda RBPT | F42: 1 | G42: 23 | H42: 0.018534595 | I42: 8
A43: Austria | B43: 2 | C43: 81 | D43: Oscar Piastri | E43: McLaren Mercedes | F43: 3 | G43: 23 | H43: 4.616 | I43: 7
A44: Austria | B44: 3 | C44: 4 | D44: Lando Norris | E44: McLaren Mercedes | F44: 2 | G44: 23 | H44: 5.348 | I44: 6
A45: Austria | B45: 4 | C45: 63 | D45: George Russell | E45: Mercedes | F45: 4 | G45: 23 | H45: 8.354 | I45: 5
A46: Austria | B46: 5 | C46: 55 | D46: Carlos Sainz | E46: Ferrari | F46: 5 | G46: 23 | H46: 9.989 | I46: 4
A47: Austria | B47: 6 | C47: 44 | D47: Lewis Hamilton | E47: Mercedes | F47: 6 | G47: 23 | H47: 11.207 | I47: 3
A48: Austria | B48: 7 | C48: 16 | D48: Charles Leclerc | E48: Ferrari | F48: 10 | G48: 23 | H48: 13.424 | I48: 2
A49: Austria | B49: 8 | C49: 11 | D49: Sergio Perez | E49: Red Bull Racing Honda RBPT | F49: 7 | G49: 23 | H49: 17.409 | I49: 1
A50: Austria | B50: 9 | C50: 20 | D50: Kevin Magnussen | E50: Haas Ferrari | F50: 11 | G50: 23 | H50: 24.067 | I50: 0
A51: Austria | B51: 10 | C51: 18 | D51: Lance Stroll | E51: Aston Martin Aramco Mercedes | F51: 12 | G51: 23 | H51: 30.175 | I51: 0
...

Sheet Quarters Points
A1: Quarters | B1: Teams | C1: Cummulative Points
A2: Q1 | B2: Red Bull Racing Honda RBPT | C2: =211+28 -> 239
A3: Q1 | B3: McLaren Mercedes | C3: =116+8 -> 124
A4: Q1 | B4: Ferrari | C4: =167+20 -> 187
A5: Q1 | B5: Mercedes | C5: =56+8 -> 64
A6: Q2 | B6: Red Bull Racing Honda RBPT | C6: =336+37 -> 373
A7: Q2 | B7: McLaren Mercedes | C7: =274+21 -> 295
A8: Q2 | B8: Ferrari | C8: =276+21 -> 297
A9: Q2 | B9: Mercedes | C9: =205+16 -> 221
A10: Q3 | B10: Red Bull Racing Honda RBPT | C10: =438+37 -> 475
A11: Q3 | B11: McLaren Mercedes | C11: =495+21 -> 516
A12: Q3 | B12: Ferrari | C12: =415+21 -> 436
A13: Q3 | B13: Mercedes | C13: =313+16 -> 329
A14: Q4 | B14: Red Bull Racing Honda RBPT | C14: =537+52 -> 589
A15: Q4 | B15: McLaren Mercedes | C15: =609+57 -> 666
A16: Q4 | B16: Ferrari | C16: =595+57 -> 652
A17: Q4 | B17: Mercedes | C17: =433+35 -> 468

Sheet Big 4 Stats
A1: Track | B1: Position | C1: No | D1: Driver | E1: Team | F1: Starting Grid | G1: Laps | H1: Time/Retired | I1: Points | J1: Set Fastest Lap | K1: Fastest Lap Time
A2: Bahrain | B2: 1 | C2: 1 | D2: Max Verstappen | E2: Red Bull Racing Honda RBPT | F2: 1 | G2: 57 | H2: 0.063712292 | I2: 26 | J2: Yes | K2: 0.0010718519
A3: Bahrain | B3: 2 | C3: 11 | D3: Sergio Perez | E3: Red Bull Racing Honda RBPT | F3: 5 | G3: 57 | H3: 22.457 | I3: 18 | J3: No | K3: 0.0010921759
A4: Bahrain | B4: 3 | C4: 55 | D4: Carlos Sainz | E4: Ferrari | F4: 4 | G4: 57 | H4: 25.11 | I4: 15 | J4: No | K4: 0.001093831
A5: Bahrain | B5: 4 | C5: 16 | D5: Charles Leclerc | E5: Ferrari | F5: 2 | G5: 57 | H5: 39.669 | I5: 12 | J5: No | K5: 0.0010890046
A6: Bahrain | B6: 5 | C6: 63 | D6: George Russell | E6: Mercedes | F6: 3 | G6: 57 | H6: 46.788 | I6: 10 | J6: No | K6: 0.0011002894
A7: Bahrain | B7: 6 | C7: 4 | D7: Lando Norris | E7: McLaren Mercedes | F7: 7 | G7: 57 | H7: 48.458 | I7: 8 | J7: No | K7: 0.0010934722
A8: Bahrain | B8: 7 | C8: 44 | D8: Lewis Hamilton | E8: Mercedes | F8: 9 | G8: 57 | H8: 50.324 | I8: 6 | J8: No | K8: 0.0010963194
A9: Bahrain | B9: 8 | C9: 81 | D9: Oscar Piastri | E9: McLaren Mercedes | F9: 8 | G9: 57 | H9: 56.082 | I9: 4 | J9: No | K9: 0.0010993403
A10: Saudi Arabia | B10: 1 | C10: 1 | D10: Max Verstappen | E10: Red Bull Racing Honda RBPT | F10: 1 | G10: 50 | H10: 0.0560564 | I10: 25 | J10: No | K10: 0.0010621875
A11: Saudi Arabia | B11: 2 | C11: 11 | D11: Sergio Perez | E11: Red Bull Racing Honda RBPT | F11: 3 | G11: 50 | H11: 13.643 | I11: 18 | J11: No | K11: 0.0010679745
A12: Saudi Arabia | B12: 3 | C12: 16 | D12: Charles Leclerc | E12: Ferrari | F12: 2 | G12: 50 | H12: 18.639 | I12: 16 | J12: Yes | K12: 0.0010605556
A13: Saudi Arabia | B13: 4 | C13: 81 | D13: Oscar Piastri | E13: McLaren Mercedes | F13: 5 | G13: 50 | H13: 32.007 | I13: 12 | J13: No | K13: 0.0010684028
... A22: Australia | B22: 5 | C22: 11 | D22: Sergio Perez | E22: Red Bull Racing Honda RBPT | F22: 6 | G22: 58 | H22: 56.309 | I22: 10 | J22: No | K22: 0.00093041667
A23: Australia | B23: 17 | C23: 63 | D23: George Russell | E23: Mercedes | F23: 7 | G23: 56 | H23: DNF | I23: 0 | J23: No | K23: 0.00092921296
A24: Australia | B24: NC | C24: 44 | D24: Lewis Hamilton | E24: Mercedes | F24: 11 | G24: 15 | H24: DNF | I24: 0 | J24: No | K24: 0.00095421296
A25: Australia | B25: NC | C25: 1 | D25: Max Verstappen | E25: Red Bull Racing Honda RBPT | F25: 1 | G25: 3 | H25: DNF | I25: 0 | J25: No | K25: 0.00096197917
A26: Japan | B26: 1 | C26: 1 | D26: Max Verstappen | E26: Red Bull Racing Honda RBPT | F26: 1 | G26: 53 | H26: 0.079439421 | I26: 26 | J26: Yes | K26: 0.0010845602
A27: Japan | B27: 2 | C27: 11 | D27: Sergio Perez | E27: Red Bull Racing Honda RBPT | F27: 2 | G27: 53 | H27: 12.535 | I27: 18 | J27: No | K27: 0.0010873264
A28: Japan | B28: 3 | C28: 55 | D28: Carlos Sainz | E28: Ferrari | F28: 4 | G28: 53 | H28: 20.866 | I28: 15 | J28: No | K28: 0.0010861227
A29: Japan | B29: 4 | C29: 16 | D29: Charles Leclerc | E29: Ferrari | F29: 8 | G29: 53 | H29: 26.522 | I29: 12 | J29: No | K29: 0.0011000463
A30: Japan | B30: 5 | C30: 4 | D30: Lando Norris | E30: McLaren Mercedes | F30: 3 | G30: 53 | H30: 29.7 | I30: 10 | J30: No | K30: 0.0011016898
A31: Japan | B31: 7 | C31: 63 | D31: George Russell | E31: Mercedes | F31: 9 | G31: 53 | H31: 45.951 | I31: 6 | J31: No | K31: 0.0010926389
A32: Japan | B32: 8 | C32: 81 | D32: Oscar Piastri | E32: McLaren Mercedes | F32: 6 | G32: 53 | H32: 47.525 | I32: 4 | J32: No | K32: 0.0010972454
A33: Japan | B33: 9 | C33: 44 | D33: Lewis Hamilton | E33: Mercedes | F33: 7 | G33: 53 | H33: 48.626 | I33: 2 | J33: No | K33: 0.0010874074
A34: China | B34: 1 | C34: 1 | D34: Max Verstappen | E34: Red Bull Racing Honda RBPT | F34: 1 | G34: 56 | H34: 0.070052708 | I34: 25 | J34: No | K34: 0.0011389583
A35: China | B35: 2 | C35: 4 | D35: Lando Norris | E35: McLaren Mercedes | F35: 4 | G35: 56 | H35: 13.773 | I35: 18 | J35: No | K35: 0.0011429514
A36: China | B36: 3 | C36: 11 | D36: Sergio Perez | E36: Red Bull Racing Honda RBPT | F36: 2 | G36: 56 | H36: 19.16 | I36: 15 | J36: No | K36: 0.0011503241
A37: China | B37: 4 | C37: 16 | D37: Charles Leclerc | E37: Ferrari | F37: 6 | G37: 56 | H37: 23.623 | I37: 12 | J37: No | K37: 0.0011502778
... A64: Monaco | B64: 7 | C64: 44 | D64: Lewis Hamilton | E64: Mercedes | F64: 7 | G64: 78 | H64: 14.908 | I64: 7 | J64: Yes | K64: 0.0008583912
A65: Monaco | B65: NC | C65: 11 | D65: Sergio Perez | E65: Red Bull Racing Honda RBPT | F65: 16 | G65: 0 | H65: DNF | I65: 0 | J65: No
A66: Canada | B66: 1 | C66: 1 | D66: Max Verstappen | E66: Red Bull Racing Honda RBPT | F66: 2 | G66: 70 | H66: 0.073471377 | I66: 25 | J66: No | K66: 0.0008746412
A67: Canada | B67: 2 | C67: 4 | D67: Lando Norris | E67: McLaren Mercedes | F67: 3 | G67: 70 | H67: 3.879 | I67: 18 | J67: No | K67: 0.00087451389
A68: Canada | B68: 3 | C68: 63 | D68: George Russell | E68: Mercedes | F68: 1 | G68: 70 | H68: 4.317 | I68: 15 | J68: No | K68: 0.00086684028
A69: Canada | B69: 4 | C69: 44 | D69: Lewis Hamilton | E69: Mercedes | F69: 7 | G69: 70 | H69: 4.915 | I69: 13 | J69: Yes | K69: 0.00086638889
A70: Canada | B70: 5 | C70: 81 | D70: Oscar Piastri | E70: McLaren Mercedes | F70: 4 | G70: 70 | H70: 10.199 | I70: 10 | J70: No | K70: 0.00088248843
A71: Canada | B71: NC | C71: 55 | D71: Carlos Sainz | E71: Ferrari | F71: 12 | G71: 52 | H71: DNF | I71: 0 | J71: No | K71: 0.00091385417
A72: Canada | B72: NC | C72: 11 | D72: Sergio Perez | E72: Red Bull Racing Honda RBPT | F72: 16 | G72: 51 | H72: DNF | I72: 0 | J72: No | K72: 0.00091225694
A73: Canada | B73: NC | C73: 16 | D73: Charles Leclerc | E73: Ferrari | F73: 11 | G73: 40 | H73: DNF | I73: 0 | J73: No | K73: 0.00099550926
A74: Spain | B74: 1 | C74: 1 | D74: Max Verstappen | E74: Red Bull Racing Honda RBPT | F74: 2 | G74: 66 | H74: 0.06134522 | I74: 25 | J74: No | K74: 0.00090018519
...

Sheet RedBull
A1: Track | B1: Position | C1: No | D1: Driver | E1: Team | F1: Starting Grid | G1: Laps | H1: Time/Retired | I1: Points | J1: Set Fastest Lap | K1: Fastest Lap Time | N1: Red Bull Points | O1: Track Index
A2: Bahrain | B2: 1 | C2: 1 | D2: Max Verstappen | E2: Red Bull Racing Honda RBPT | F2: 1 | G2: 57 | H2: 0.063712292 | I2: 26 | J2: Yes | K2: 0.0010718519 | L2: =I2+I3 -> 44 | N2: 44 | O2: =_xlfn.XLOOKUP(A2,Formula1_2024season_raceResults!A:A,Formula1_2024season_raceResults!L:L) -> 1
A3: Bahrain | B3: 2 | C3: 11 | D3: Sergio Perez | E3: Red Bull Racing Honda RBPT | F3: 5 | G3: 57 | H3: 22.457 | I3: 18 | J3: No | K3: 0.0010921759 | O3: =_xlfn.XLOOKUP(A3,Formula1_2024season_raceResults!A:A,Formula1_2024season_raceResults!L:L) -> 1
A4: Saudi Arabia | B4: 1 | C4: 1 | D4: Max Verstappen | E4: Red Bull Racing Honda RBPT | F4: 1 | G4: 50 | H4: 0.0560564 | I4: 25 | J4: No | K4: 0.0010621875 | L4: =I4+I5 -> 43 | N4: 43 | O4: =_xlfn.XLOOKUP(A4,Formula1_2024season_raceResults!A:A,Formula1_2024season_raceResults!L:L) -> 2
A5: Saudi Arabia | B5: 2 | C5: 11 | D5: Sergio Perez | E5: Red Bull Racing Honda RBPT | F5: 3 | G5: 50 | H5: 13.643 | I5: 18 | J5: No | K5: 0.0010679745 | O5: =_xlfn.XLOOKUP(A5,Formula1_2024season_raceResults!A:A,Formula1_2024season_raceResults!L:L) -> 2
A6: Australia | B6: 5 | C6: 11 | D6: Sergio Perez | E6: Red Bull Racing Honda RBPT | F6: 6 | G6: 58 | H6: 56.309 | I6: 10 | J6: No | K6: 0.00093041667 | L6: =I6+I7 -> 10 | N6: 10 | O6: =_xlfn.XLOOKUP(A6,Formula1_2024season_raceResults!A:A,Formula1_2024season_raceResults!L:L) -> 3
A7: Australia | C7: 1 | D7: Max Verstappen | E7: Red Bull Racing Honda RBPT | F7: 1 | G7: 3 | H7: DNF | I7: 0 | J7: No | K7: 0.00096197917 | O7: =_xlfn.XLOOKUP(A7,Formula1_2024season_raceResults!A:A,Formula1_2024season_raceResults!L:L) -> 3
A8: Japan | B8: 1 | C8: 1 | D8: Max Verstappen | E8: Red Bull Racing Honda RBPT | F8: 1 | G8: 53 | H8: 0.079439421 | I8: 26 | J8: Yes | K8: 0.0010845602 | L8: =I8+I9 -> 44 | N8: 44 | O8: =_xlfn.XLOOKUP(A8,Formula1_2024season_raceResults!A:A,Formula1_2024season_raceResults!L:L) -> 4
A9: Japan | B9: 2 | C9: 11 | D9: Sergio Perez | E9: Red Bull Racing Honda RBPT | F9: 2 | G9: 53 | H9: 12.535 | I9: 18 | J9: No | K9: 0.0010873264 | O9: =_xlfn.XLOOKUP(A9,Formula1_2024season_raceResults!A:A,Formula1_2024season_raceResults!L:L) -> 4
A10: China | B10: 1 | C10: 1 | D10: Max Verstappen | E10: Red Bull Racing Honda RBPT | F10: 1 | G10: 56 | H10: 0.070052708 | I10: 25 | J10: No | K10: 0.0011389583 | L10: =I10+I11 -> 40 | N10: 40 | O10: =_xlfn.XLOOKUP(A10,Formula1_2024season_raceResults!A:A,Formula1_2024season_raceResults!L:L) -> 5
A11: China | B11: 3 | C11: 11 | D11: Sergio Perez | E11: Red Bull Racing Honda RBPT | F11: 2 | G11: 56 | H11: 19.16 | I11: 15 | J11: No | K11: 0.0011503241 | O11: =_xlfn.XLOOKUP(A11,Formula1_2024season_raceResults!A:A,Formula1_2024season_raceResults!L:L) -> 5
A12: Miami | B12: 2 | C12: 1 | D12: Max Verstappen | E12: Red Bull Racing Honda RBPT | F12: 1 | G12: 57 | H12: 7.612 | I12: 18 | J12: No | K12: 0.0010562616 | L12: =I12+I13 -> 30 | N12: 30 | O12: =_xlfn.XLOOKUP(A12,Formula1_2024season_raceResults!A:A,Formula1_2024season_raceResults!L:L) -> 6
A13: Miami | B13: 4 | C13: 11 | D13: Sergio Perez | E13: Red Bull Racing Honda RBPT | F13: 4 | G13: 57 | H13: 14.65 | I13: 12 | J13: No | K13: 0.0010515625 | O13: =_xlfn.XLOOKUP(A13,Formula1_2024season_raceResults!A:A,Formula1_2024season_raceResults!L:L) -> 6
A14: Emilia Romagna | B14: 1 | C14: 1 | D14: Max Verstappen | E14: Red Bull Racing Honda RBPT | F14: 1 | G14: 63 | H14: 0.059320046 | I14: 25 | J14: No | K14: 0.00093016204 | L14: =I14+I15 -> 29 | N14: 29 | O14: =_xlfn.XLOOKUP(A14,Formula1_2024season_raceResults!A:A,Formula1_2024season_raceResults!L:L) -> 7
A15: Emilia Romagna | B15: 8 | C15: 11 | D15: Sergio Perez | E15: Red Bull Racing Honda RBPT | F15: 11 | G15: 63 | H15: 54.776 | I15: 4 | J15: No | K15: 0.00092229167 | O15: =_xlfn.XLOOKUP(A15,Formula1_2024season_raceResults!A:A,Formula1_2024season_raceResults!L:L) -> 7
A16: Monaco | B16: 6 | C16: 1 | D16: Max Verstappen | E16: Red Bull Racing Honda RBPT | F16: 6 | G16: 78 | H16: 13.853 | I16: 8 | J16: No | K16: 0.00086306713 | L16: =I16+I17 -> 8 | N16: 8 | O16: =_xlfn.XLOOKUP(A16,Formula1_2024season_raceResults!A:A,Formula1_2024season_raceResults!L:L) -> 8
A17: Monaco | C17: 11 | D17: Sergio Perez | E17: Red Bull Racing Honda RBPT | F17: 16 | G17: 0 | H17: DNF | I17: 0 | J17: No | O17: =_xlfn.XLOOKUP(A17,Formula1_2024season_raceResults!A:A,Formula1_2024season_raceResults!L:L) -> 8
A18: Canada | B18: 1 | C18: 1 | D18: Max Verstappen | E18: Red Bull Racing Honda RBPT | F18: 2 | G18: 70 | H18: 0.073471377 | I18: 25 | J18: No | K18: 0.0008746412 | L18: =I18+I19 -> 25 | N18: 25 | O18: =_xlfn.XLOOKUP(A18,Formula1_2024season_raceResults!A:A,Formula1_2024season_raceResults!L:L) -> 9
A19: Canada | C19: 11 | D19: Sergio Perez | E19: Red Bull Racing Honda RBPT | F19: 16 | G19: 51 | H19: DNF | I19: 0 | J19: No | K19: 0.00091225694 | O19: =_xlfn.XLOOKUP(A19,Formula1_2024season_raceResults!A:A,Formula1_2024season_raceResults!L:L) -> 9
A20: Spain | B20: 1 | C20: 1 | D20: Max Verstappen | E20: Red Bull Racing Honda RBPT | F20: 2 | G20: 66 | H20: 0.06134522 | I20: 25 | J20: No | K20: 0.00090018519 | L20: =I20+I21 -> 29 | N20: 29 | O20: =_xlfn.XLOOKUP(A20,Formula1_2024season_raceResults!A:A,Formula1_2024season_raceResults!L:L) -> 10
A21: Spain | B21: 8 | C21: 11 | D21: Sergio Perez | E21: Red Bull Racing Honda RBPT | F21: 11 | G21: 66 | H21: 59.524 | I21: 4 | J21: No | K21: 0.00090028935 | O21: =_xlfn.XLOOKUP(A21,Formula1_2024season_raceResults!A:A,Formula1_2024season_raceResults!L:L) -> 10
A22: Austria | B22: 5 | C22: 1 | D22: Max Verstappen | E22: Red Bull Racing Honda RBPT | F22: 1 | G22: 71 | H22: 37.253 | I22: 10 | J22: No | K22: 0.00078378472 | L22: =I22+I23 -> 16 | N22: 16 | O22: =_xlfn.XLOOKUP(A22,Formula1_2024season_raceResults!A:A,Formula1_2024season_raceResults!L:L) -> 11
A23: Austria | B23: 7 | C23: 11 | D23: Sergio Perez | E23: Red Bull Racing Honda RBPT | F23: 8 | G23: 71 | H23: 54.672 | I23: 6 | J23: No | K23: 0.00080664352 | O23: =_xlfn.XLOOKUP(A23,Formula1_2024season_raceResults!A:A,Formula1_2024season_raceResults!L:L) -> 11
A24: Great Britain | B24: 2 | C24: 1 | D24: Max Verstappen | E24: Red Bull Racing Honda RBPT | F24: 4 | G24: 52 | H24: 1.465 | I24: 18 | J24: No | K24: 0.001029537 | L24: =I24+I25 -> 18 | N24: 18 | O24: =_xlfn.XLOOKUP(A24,Formula1_2024season_raceResults!A:A,Formula1_2024season_raceResults!L:L) -> 12
A25: Great Britain | B25: 17 | C25: 11 | D25: Sergio Perez | E25: Red Bull Racing Honda RBPT | F25: 20 | G25: 50 | H25: +2 laps | I25: 0 | J25: No | K25: 0.0010382755 | O25: =_xlfn.XLOOKUP(A25,Formula1_2024season_raceResults!A:A,Formula1_2024season_raceResults!L:L) -> 12
A26: Hungary | B26: 5 | C26: 1 | D26: Max Verstappen | E26: Red Bull Racing Honda RBPT | F26: 3 | G26: 70 | H26: 21.349 | I26: 10 | J26: No | K26: 0.00093643519 | L26: =I26+I27 -> 16 | N26: 16 | O26: =_xlfn.XLOOKUP(A26,Formula1_2024season_raceResults!A:A,Formula1_2024season_raceResults!L:L) -> 13
A27: Hungary | B27: 7 | C27: 11 | D27: Sergio Perez | E27: Red Bull Racing Honda RBPT | F27: 16 | G27: 70 | H27: 39.792 | I27: 6 | J27: No | K27: 0.00093861111 | O27: =_xlfn.XLOOKUP(A27,Formula1_2024season_raceResults!A:A,Formula1_2024season_raceResults!L:L) -> 13
A28: Belgium | B28: 4 | C28: 1 | D28: Max Verstappen | E28: Red Bull Racing Honda RBPT | F28: 11 | G28: 44 | H28: 9.226 | I28: 12 | J28: No | K28: 0.0012283333 | L28: =I28+I29 -> 19 | N28: 19 | O28: =_xlfn.XLOOKUP(A28,Formula1_2024season_raceResults!A:A,Formula1_2024season_raceResults!L:L) -> 14
A29: Belgium | B29: 7 | C29: 11 | D29: Sergio Perez | E29: Red Bull Racing Honda RBPT | F29: 2 | G29: 44 | H29: 3.195 | I29: 7 | J29: Yes | K29: 0.0012118171 | O29: =_xlfn.XLOOKUP(A29,Formula1_2024season_raceResults!A:A,Formula1_2024season_raceResults!L:L) -> 14
A30: Netherlands | B30: 2 | C30: 1 | D30: Max Verstappen | E30: Red Bull Racing Honda RBPT | F30: 2 | G30: 72 | H30: 22.896 | I30: 18 | J30: No | K30: 0.00086518519 | L30: =I30+I31 -> 26 | N30: 26 | O30: =_xlfn.XLOOKUP(A30,Formula1_2024season_raceResults!A:A,Formula1_2024season_raceResults!L:L) -> 15
A31: Netherlands | B31: 6 | C31: 11 | D31: Sergio Perez | E31: Red Bull Racing Honda RBPT | F31: 5 | G31: 72 | H31: 39.542 | I31: 8 | J31: No | K31: 0.00086327546 | O31: =_xlfn.XLOOKUP(A31,Formula1_2024season_raceResults!A:A,Formula1_2024season_raceResults!L:L) -> 15
A32: Italy | B32: 6 | C32: 1 | D32: Max Verstappen | E32: Red Bull Racing Honda RBPT | F32: 7 | G32: 53 | H32: 37.932 | I32: 8 | J32: No | K32: 0.00094612269 | L32: =I32+I33 -> 12 | N32: 12 | O32: =_xlfn.XLOOKUP(A32,Formula1_2024season_raceResults!A:A,Formula1_2024season_raceResults!L:L) -> 16
A33: Italy | B33: 8 | C33: 11 | D33: Sergio Perez | E33: Red Bull Racing Honda RBPT | F33: 8 | G33: 53 | H33: 54.148 | I33: 4 | J33: No | K33: 0.0009603125 | O33: =_xlfn.XLOOKUP(A33,Formula1_2024season_raceResults!A:A,Formula1_2024season_raceResults!L:L) -> 16
A34: Azerbaijan | B34: 5 | C34: 1 | D34: Max Verstappen | E34: Red Bull Racing Honda RBPT | F34: 6 | G34: 51 | H34: 77.098 | I34: 10 | J34: No | K34: 0.001236088 | L34: =I34+I35 -> 10 | N34: 10 | O34: =_xlfn.XLOOKUP(A34,Formula1_2024season_raceResults!A:A,Formula1_2024season_raceResults!L:L) -> 17
A35: Azerbaijan | B35: 17 | C35: 11 | D35: Sergio Perez | E35: Red Bull Racing Honda RBPT | F35: 4 | G35: 49 | H35: DNF | I35: 0 | J35: No | K35: 0.0012385764 | O35: =_xlfn.XLOOKUP(A35,Formula1_2024season_raceResults!A:A,Formula1_2024season_raceResults!L:L) -> 17
A36: Singapore | B36: 2 | C36: 1 | D36: Max Verstappen | E36: Red Bull Racing Honda RBPT | F36: 2 | G36: 62 | H36: 20.945 | I36: 18 | J36: No | K36: 0.0011107292 | L36: =I36+I37 -> 19 | N36: 19 | O36: =_xlfn.XLOOKUP(A36,Formula1_2024season_raceResults!A:A,Formula1_2024season_raceResults!L:L) -> 18
A37: Singapore | B37: 10 | C37: 11 | D37: Sergio Perez | E37: Red Bull Racing Honda RBPT | F37: 13 | G37: 61 | H37: +1 lap | I37: 1 | J37: No | K37: 0.001128206 | O37: =_xlfn.XLOOKUP(A37,Formula1_2024season_raceResults!A:A,Formula1_2024season_raceResults!L:L) -> 18
A38: United States | B38: 3 | C38: 1 | D38: Max Verstappen | E38: Red Bull Racing Honda RBPT | F38: 2 | G38: 56 | H38: 19.412 | I38: 15 | J38: No | K38: 0.0011356134 | L38: =I38+I39 -> 21 | N38: 21 | O38: =_xlfn.XLOOKUP(A38,Formula1_2024season_raceResults!A:A,Formula1_2024season_raceResults!L:L) -> 19
A39: United States | B39: 7 | C39: 11 | D39: Sergio Perez | E39: Red Bull Racing Honda RBPT | F39: 9 | G39: 56 | H39: 59.072 | I39: 6 | J39: No | K39: 0.0011402083 | O39: =_xlfn.XLOOKUP(A39,Formula1_2024season_raceResults!A:A,Formula1_2024season_raceResults!L:L) -> 19
A40: Mexico | B40: 6 | C40: 1 | D40: Max Verstappen | E40: Red Bull Racing Honda RBPT | F40: 2 | G40: 71 | H40: 59.558 | I40: 8 | J40: No | K40: 0.00093601852 | L40: =I40+I41 -> 8 | N40: 8 | O40: =_xlfn.XLOOKUP(A40,Formula1_2024season_raceResults!A:A,Formula1_2024season_raceResults!L:L) -> 20
...

Sheet Checo
A1: Track | B1: Position | C1: No | D1: Driver | E1: Team | F1: Starting Grid | G1: Laps | H1: Time/Retired | I1: Points | J1: Set Fastest Lap | K1: Fastest Lap Time
A2: Bahrain | B2: 2 | C2: 11 | D2: Sergio Perez | E2: Red Bull Racing Honda RBPT | F2: 5 | G2: 57 | H2: 22.457 | I2: 18 | J2: No | K2: 0.0010921759
A3: Saudi Arabia | B3: 2 | C3: 11 | D3: Sergio Perez | E3: Red Bull Racing Honda RBPT | F3: 3 | G3: 50 | H3: 13.643 | I3: 18 | J3: No | K3: 0.0010679745
A4: Australia | B4: 5 | C4: 11 | D4: Sergio Perez | E4: Red Bull Racing Honda RBPT | F4: 6 | G4: 58 | H4: 56.309 | I4: 10 | J4: No | K4: 0.00093041667
A5: Japan | B5: 2 | C5: 11 | D5: Sergio Perez | E5: Red Bull Racing Honda RBPT | F5: 2 | G5: 53 | H5: 12.535 | I5: 18 | J5: No | K5: 0.0010873264
A6: China | B6: 3 | C6: 11 | D6: Sergio Perez | E6: Red Bull Racing Honda RBPT | F6: 2 | G6: 56 | H6: 19.16 | I6: 15 | J6: No | K6: 0.0011503241
A7: Miami | B7: 4 | C7: 11 | D7: Sergio Perez | E7: Red Bull Racing Honda RBPT | F7: 4 | G7: 57 | H7: 14.65 | I7: 12 | J7: No | K7: 0.0010515625
A8: Emilia Romagna | B8: 8 | C8: 11 | D8: Sergio Perez | E8: Red Bull Racing Honda RBPT | F8: 11 | G8: 63 | H8: 54.776 | I8: 4 | J8: No | K8: 0.00092229167
A9: Monaco | B9: NC | C9: 11 | D9: Sergio Perez | E9: Red Bull Racing Honda RBPT | F9: 16 | G9: 0 | H9: DNF | I9: 0 | J9: No
A10: Canada | B10: NC | C10: 11 | D10: Sergio Perez | E10: Red Bull Racing Honda RBPT | F10: 16 | G10: 51 | H10: DNF | I10: 0 | J10: No | K10: 0.00091225694
A11: Spain | B11: 8 | C11: 11 | D11: Sergio Perez | E11: Red Bull Racing Honda RBPT | F11: 11 | G11: 66 | H11: 59.524 | I11: 4 | J11: No | K11: 0.00090028935
A12: Austria | B12: 7 | C12: 11 | D12: Sergio Perez | E12: Red Bull Racing Honda RBPT | F12: 8 | G12: 71 | H12: 54.672 | I12: 6 | J12: No | K12: 0.00080664352
A13: Great Britain | B13: 17 | C13: 11 | D13: Sergio Perez | E13: Red Bull Racing Honda RBPT | F13: 20 | G13: 50 | H13: +2 laps | I13: 0 | J13: No | K13: 0.0010382755
A14: Hungary | B14: 7 | C14: 11 | D14: Sergio Perez | E14: Red Bull Racing Honda RBPT | F14: 16 | G14: 70 | H14: 39.792 | I14: 6 | J14: No | K14: 0.00093861111
A15: Belgium | B15: 7 | C15: 11 | D15: Sergio Perez | E15: Red Bull Racing Honda RBPT | F15: 2 | G15: 44 | H15: 3.195 | I15: 7 | J15: Yes | K15: 0.0012118171
A16: Netherlands | B16: 6 | C16: 11 | D16: Sergio Perez | E16: Red Bull Racing Honda RBPT | F16: 5 | G16: 72 | H16: 39.542 | I16: 8 | J16: No | K16: 0.00086327546
A17: Italy | B17: 8 | C17: 11 | D17: Sergio Perez | E17: Red Bull Racing Honda RBPT | F17: 8 | G17: 53 | H17: 54.148 | I17: 4 | J17: No | K17: 0.0009603125
A18: Azerbaijan | B18: 17 | C18: 11 | D18: Sergio Perez | E18: Red Bull Racing Honda RBPT | F18: 4 | G18: 49 | H18: DNF | I18: 0 | J18: No | K18: 0.0012385764
A19: Singapore | B19: 10 | C19: 11 | D19: Sergio Perez | E19: Red Bull Racing Honda RBPT | F19: 13 | G19: 61 | H19: +1 lap | I19: 1 | J19: No | K19: 0.001128206
A20: United States | B20: 7 | C20: 11 | D20: Sergio Perez | E20: Red Bull Racing Honda RBPT | F20: 9 | G20: 56 | H20: 59.072 | I20: 6 | J20: No | K20: 0.0011402083
A21: Mexico | B21: 17 | C21: 11 | D21: Sergio Perez | E21: Red Bull Racing Honda RBPT | F21: 18 | G21: 70 | H21: +1 lap | I21: 0 | J21: No | K21: 0.00091677083
A22: Brazil | B22: 11 | C22: 11 | D22: Sergio Perez | E22: Red Bull Racing Honda RBPT | F22: 12 | G22: 69 | H22: 51.531 | I22: 0 | J22: No | K22: 0.00095072917
A23: Las Vegas | B23: 10 | C23: 11 | D23: Sergio Perez | E23: Red Bull Racing Honda RBPT | F23: 15 | G23: 50 | H23: 63.114 | I23: 1 | J23: No | K23: 0.0011148843
A24: Qatar | B24: NC | C24: 11 | D24: Sergio Perez | E24: Red Bull Racing Honda RBPT | F24: 9 | G24: 38 | H24: DNF | I24: 0 | J24: No | K24: 0.00098712963
A25: Abu Dhabi | B25: NC | C25: 11 | D25: Sergio Perez | E25: Red Bull Racing Honda RBPT | F25: 10 | G25: 0 | H25: DNF | I25: 0 | J25: No

Sheet Max vs Checo
A1: Track | B1: Position | C1: No | D1: Driver | E1: Starting Grid | F1: Laps | G1: Time/Retired | H1: Points | I1: Set Fastest Lap | J1: Fastest Lap Time
A2: Bahrain | B2: 1 | C2: 1 | D2: Max Verstappen | E2: 1 | F2: 57 | G2: 0.063712292 | H2: 26 | I2: Yes | J2: 0.0010718519
A3: Bahrain | B3: 2 | C3: 11 | D3: Sergio Perez | E3: 5 | F3: 57 | G3: 22.457 | H3: 18 | I3: No | J3: 0.0010921759
A4: Saudi Arabia | B4: 1 | C4: 1 | D4: Max Verstappen | E4: 1 | F4: 50 | G4: 0.0560564 | H4: 25 | I4: No | J4: 0.0010621875
A5: Saudi Arabia | B5: 2 | C5: 11 | D5: Sergio Perez | E5: 3 | F5: 50 | G5: 13.643 | H5: 18 | I5: No | J5: 0.0010679745
A6: Australia | B6: 5 | C6: 11 | D6: Sergio Perez | E6: 6 | F6: 58 | G6: 56.309 | H6: 10 | I6: No | J6: 0.00093041667
A7: Australia | B7: NC | C7: 1 | D7: Max Verstappen | E7: 1 | F7: 3 | G7: DNF | H7: 0 | I7: No | J7: 0.00096197917
A8: Japan | B8: 1 | C8: 1 | D8: Max Verstappen | E8: 1 | F8: 53 | G8: 0.079439421 | H8: 26 | I8: Yes | J8: 0.0010845602
A9: Japan | B9: 2 | C9: 11 | D9: Sergio Perez | E9: 2 | F9: 53 | G9: 12.535 | H9: 18 | I9: No | J9: 0.0010873264
A10: China | B10: 1 | C10: 1 | D10: Max Verstappen | E10: 1 | F10: 56 | G10: 0.070052708 | H10: 25 | I10: No | J10: 0.0011389583
A11: China | B11: 3 | C11: 11 | D11: Sergio Perez | E11: 2 | F11: 56 | G11: 19.16 | H11: 15 | I11: No | J11: 0.0011503241
A12: Miami | B12: 2 | C12: 1 | D12: Max Verstappen | E12: 1 | F12: 57 | G12: 7.612 | H12: 18 | I12: No | J12: 0.0010562616
A13: Miami | B13: 4 | C13: 11 | D13: Sergio Perez | E13: 4 | F13: 57 | G13: 14.65 | H13: 12 | I13: No | J13: 0.0010515625
A14: Emilia Romagna | B14: 1 | C14: 1 | D14: Max Verstappen | E14: 1 | F14: 63 | G14: 0.059320046 | H14: 25 | I14: No | J14: 0.00093016204
A15: Emilia Romagna | B15: 8 | C15: 11 | D15: Sergio Perez | E15: 11 | F15: 63 | G15: 54.776 | H15: 4 | I15: No | J15: 0.00092229167
A16: Monaco | B16: 6 | C16: 1 | D16: Max Verstappen | E16: 6 | F16: 78 | G16: 13.853 | H16: 8 | I16: No | J16: 0.00086306713
A17: Monaco | B17: NC | C17: 11 | D17: Sergio Perez | E17: 16 | F17: 0 | G17: DNF | H17: 0 | I17: No
A18: Canada | B18: 1 | C18: 1 | D18: Max Verstappen | E18: 2 | F18: 70 | G18: 0.073471377 | H18: 25 | I18: No | J18: 0.0008746412
A19: Canada | B19: NC | C19: 11 | D19: Sergio Perez | E19: 16 | F19: 51 | G19: DNF | H19: 0 | I19: No | J19: 0.00091225694
A20: Spain | B20: 1 | C20: 1 | D20: Max Verstappen | E20: 2 | F20: 66 | G20: 0.06134522 | H20: 25 | I20: No | J20: 0.00090018519
A21: Spain | B21: 8 | C21: 11 | D21: Sergio Perez | E21: 11 | F21: 66 | G21: 59.524 | H21: 4 | I21: No | J21: 0.00090028935
A22: Austria | B22: 5 | C22: 1 | D22: Max Verstappen | E22: 1 | F22: 71 | G22: 37.253 | H22: 10 | I22: No | J22: 0.00078378472
A23: Austria | B23: 7 | C23: 11 | D23: Sergio Perez | E23: 8 | F23: 71 | G23: 54.672 | H23: 6 | I23: No | J23: 0.00080664352
A24: Great Britain | B24: 2 | C24: 1 | D24: Max Verstappen | E24: 4 | F24: 52 | G24: 1.465 | H24: 18 | I24: No | J24: 0.001029537
A25: Great Britain | B25: 17 | C25: 11 | D25: Sergio Perez | E25: 20 | F25: 50 | G25: +2 laps | H25: 0 | I25: No | J25: 0.0010382755
A26: Hungary | B26: 5 | C26: 1 | D26: Max Verstappen | E26: 3 | F26: 70 | G26: 21.349 | H26: 10 | I26: No | J26: 0.00093643519
A27: Hungary | B27: 7 | C27: 11 | D27: Sergio Perez | E27: 16 | F27: 70 | G27: 39.792 | H27: 6 | I27: No | J27: 0.00093861111
A28: Belgium | B28: 4 | C28: 1 | D28: Max Verstappen | E28: 11 | F28: 44 | G28: 9.226 | H28: 12 | I28: No | J28: 0.0012283333
A29: Belgium | B29: 7 | C29: 11 | D29: Sergio Perez | E29: 2 | F29: 44 | G29: 3.195 | H29: 7 | I29: Yes | J29: 0.0012118171
A30: Netherlands | B30: 2 | C30: 1 | D30: Max Verstappen | E30: 2 | F30: 72 | G30: 22.896 | H30: 18 | I30: No | J30: 0.00086518519
A31: Netherlands | B31: 6 | C31: 11 | D31: Sergio Perez | E31: 5 | F31: 72 | G31: 39.542 | H31: 8 | I31: No | J31: 0.00086327546
A32: Italy | B32: 6 | C32: 1 | D32: Max Verstappen | E32: 7 | F32: 53 | G32: 37.932 | H32: 8 | I32: No | J32: 0.00094612269
A33: Italy | B33: 8 | C33: 11 | D33: Sergio Perez | E33: 8 | F33: 53 | G33: 54.148 | H33: 4 | I33: No | J33: 0.0009603125
A34: Azerbaijan | B34: 5 | C34: 1 | D34: Max Verstappen | E34: 6 | F34: 51 | G34: 77.098 | H34: 10 | I34: No | J34: 0.001236088
A35: Azerbaijan | B35: 17 | C35: 11 | D35: Sergio Perez | E35: 4 | F35: 49 | G35: DNF | H35: 0 | I35: No | J35: 0.0012385764
A36: Singapore | B36: 2 | C36: 1 | D36: Max Verstappen | E36: 2 | F36: 62 | G36: 20.945 | H36: 18 | I36: No | J36: 0.0011107292
A37: Singapore | B37: 10 | C37: 11 | D37: Sergio Perez | E37: 13 | F37: 61 | G37: +1 lap | H37: 1 | I37: No | J37: 0.001128206
A38: United States | B38: 3 | C38: 1 | D38: Max Verstappen | E38: 2 | F38: 56 | G38: 19.412 | H38: 15 | I38: No | J38: 0.0011356134
A39: United States | B39: 7 | C39: 11 | D39: Sergio Perez | E39: 9 | F39: 56 | G39: 59.072 | H39: 6 | I39: No | J39: 0.0011402083
A40: Mexico | B40: 6 | C40: 1 | D40: Max Verstappen | E40: 2 | F40: 71 | G40: 59.558 | H40: 8 | I40: No | J40: 0.00093601852
...

Sheet Max vs Checo vs HD
A1: Track | B1: Position | C1: No | D1: Driver | E1: Starting Grid | F1: Laps | G1: Time/Retired | H1: Points | I1: Set Fastest Lap | J1: Fastest Lap Time | L1: Points | M1: Cum points PvM | N1: Cum Points MvH
A2: Bahrain | B2: 1 | C2: 1 | D2: Max Verstappen | E2: 1 | F2: 57 | G2: 0.063712292 | H2: 26 | I2: Yes | J2: 0.0010718519 | L2: 26 | M2: =SUM($L$2:L2) -> 26
A3: Bahrain | B3: 2 | C3: 11 | D3: Sergio Perez | E3: 5 | F3: 57 | G3: 22.457 | H3: 18 | I3: No | J3: 0.0010921759 | L3: 18 | M3: =SUM($L$2:L3) -> 44
A4: Bahrain | D4: Hypothetical Driver | H4: 6 | L4: 25
A5: Saudi Arabia | B5: 1 | C5: 1 | D5: Max Verstappen | E5: 1 | F5: 50 | G5: 0.0560564 | H5: 25 | I5: No | J5: 0.0010621875 | L5: 18 | M5: =SUM($L$2:L5) -> 87
A6: Saudi Arabia | B6: 2 | C6: 11 | D6: Sergio Perez | E6: 3 | F6: 50 | G6: 13.643 | H6: 18 | I6: No | J6: 0.0010679745 | L6: 10 | M6: =SUM($L$2:L6) -> 97
A7: Saudi Arabia | D7: Hypothetical Driver | H7: 6 | L7: 0
A8: Australia | B8: 5 | C8: 11 | D8: Sergio Perez | E8: 6 | F8: 58 | G8: 56.309 | H8: 10 | I8: No | J8: 0.00093041667 | L8: 26 | M8: =SUM($L$2:L8) -> 123
A9: Australia | B9: NC | C9: 1 | D9: Max Verstappen | E9: 1 | F9: 3 | G9: DNF | H9: 0 | I9: No | J9: 0.00096197917 | L9: 18 | M9: =SUM($L$2:L9) -> 141
A10: Australia | D10: Hypothetical Driver | H10: 6 | L10: 25
A11: Japan | B11: 1 | C11: 1 | D11: Max Verstappen | E11: 1 | F11: 53 | G11: 0.079439421 | H11: 26 | I11: Yes | J11: 0.0010845602 | L11: 15 | M11: =SUM($L$2:L11) -> 181
A12: Japan | B12: 2 | C12: 11 | D12: Sergio Perez | E12: 2 | F12: 53 | G12: 12.535 | H12: 18 | I12: No | J12: 0.0010873264 | L12: 18 | M12: =SUM($L$2:L12) -> 199
A13: Japan | D13: Hypothetical Driver | H13: 6 | L13: 12
A14: China | B14: 1 | C14: 1 | D14: Max Verstappen | E14: 1 | F14: 56 | G14: 0.070052708 | H14: 25 | I14: No | J14: 0.0011389583 | L14: 25 | M14: =SUM($L$2:L14) -> 236
A15: China | B15: 3 | C15: 11 | D15: Sergio Perez | E15: 2 | F15: 56 | G15: 19.16 | H15: 15 | I15: No | J15: 0.0011503241 | L15: 4 | M15: =SUM($L$2:L15) -> 240
A16: China | D16: Hypothetical Driver | H16: 6 | L16: 8
A17: Miami | B17: 2 | C17: 1 | D17: Max Verstappen | E17: 1 | F17: 57 | G17: 7.612 | H17: 18 | I17: No | J17: 0.0010562616 | L17: 0 | M17: =SUM($L$2:L17) -> 248
A18: Miami | B18: 4 | C18: 11 | D18: Sergio Perez | E18: 4 | F18: 57 | G18: 14.65 | H18: 12 | I18: No | J18: 0.0010515625 | L18: 25 | M18: =SUM($L$2:L18) -> 273
A19: Miami | D19: Hypothetical Driver | H19: 6 | L19: 0
A20: Emilia Romagna | B20: 1 | C20: 1 | D20: Max Verstappen | E20: 1 | F20: 63 | G20: 0.059320046 | H20: 25 | I20: No | J20: 0.00093016204 | L20: 25 | M20: =SUM($L$2:L20) -> 298
A21: Emilia Romagna | B21: 8 | C21: 11 | D21: Sergio Perez | E21: 11 | F21: 63 | G21: 54.776 | H21: 4 | I21: No | J21: 0.00092229167 | L21: 4 | M21: =SUM($L$2:L21) -> 302
A22: Emilia Romagna | D22: Hypothetical Driver | H22: 6 | L22: 10
A23: Monaco | B23: 6 | C23: 1 | D23: Max Verstappen | E23: 6 | F23: 78 | G23: 13.853 | H23: 8 | I23: No | J23: 0.00086306713 | L23: 6 | M23: =SUM($L$2:L23) -> 318
A24: Monaco | B24: NC | C24: 11 | D24: Sergio Perez | E24: 16 | F24: 0 | G24: DNF | H24: 0 | I24: No | L24: 18 | M24: =SUM($L$2:L24) -> 336
A25: Monaco | D25: Hypothetical Driver | H25: 6 | L25: 0
A26: Canada | B26: 1 | C26: 1 | D26: Max Verstappen | E26: 2 | F26: 70 | G26: 0.073471377 | H26: 25 | I26: No | J26: 0.0008746412 | L26: 10 | M26: =SUM($L$2:L26) -> 346
A27: Canada | B27: NC | C27: 11 | D27: Sergio Perez | E27: 16 | F27: 51 | G27: DNF | H27: 0 | I27: No | J27: 0.00091225694 | L27: 6 | M27: =SUM($L$2:L27) -> 352
A28: Canada | D28: Hypothetical Driver | H28: 6 | L28: 12
A29: Spain | B29: 1 | C29: 1 | D29: Max Verstappen | E29: 2 | F29: 66 | G29: 0.06134522 | H29: 25 | I29: No | J29: 0.00090018519 | L29: 7 | M29: =SUM($L$2:L29) -> 371
A30: Spain | B30: 8 | C30: 11 | D30: Sergio Perez | E30: 11 | F30: 66 | G30: 59.524 | H30: 4 | I30: No | J30: 0.00090028935 | L30: 18 | M30: =SUM($L$2:L30) -> 389
A31: Spain | D31: Hypothetical Driver | H31: 6 | L31: 8
A32: Austria | B32: 5 | C32: 1 | D32: Max Verstappen | E32: 1 | F32: 71 | G32: 37.253 | H32: 10 | I32: No | J32: 0.00078378472 | L32: 8 | M32: =SUM($L$2:L32) -> 405
A33: Austria | B33: 7 | C33: 11 | D33: Sergio Perez | E33: 8 | F33: 71 | G33: 54.672 | H33: 6 | I33: No | J33: 0.00080664352 | L33: 4 | M33: =SUM($L$2:L33) -> 409
A34: Austria | D34: Hypothetical Driver | H34: 6 | L34: 10
A35: Great Britain | B35: 2 | C35: 1 | D35: Max Verstappen | E35: 4 | F35: 52 | G35: 1.465 | H35: 18 | I35: No | J35: 0.001029537 | L35: 0 | M35: =SUM($L$2:L35) -> 419
A36: Great Britain | B36: 17 | C36: 11 | D36: Sergio Perez | E36: 20 | F36: 50 | G36: +2 laps | H36: 0 | I36: No | J36: 0.0010382755 | L36: 18 | M36: =SUM($L$2:L36) -> 437
A37: Great Britain | D37: Hypothetical Driver | H37: 6 | L37: 1
A38: Hungary | B38: 5 | C38: 1 | D38: Max Verstappen | E38: 3 | F38: 70 | G38: 21.349 | H38: 10 | I38: No | J38: 0.00093643519 | L38: 15 | M38: =SUM($L$2:L38) -> 453
A39: Hungary | B39: 7 | C39: 11 | D39: Sergio Perez | E39: 16 | F39: 70 | G39: 39.792 | H39: 6 | I39: No | J39: 0.00093861111 | L39: 6 | M39: =SUM($L$2:L39) -> 459
A40: Hungary | D40: Hypothetical Driver | H40: 6 | L40: 8
...
